#VRML_SIM R2023a utf8

EXTERNPROTO "https://raw.githubusercontent.com/cyberbotics/webots/R2023a/projects/objects/backgrounds/protos/TexturedBackground.proto"
EXTERNPROTO "https://raw.githubusercontent.com/cyberbotics/webots/R2023a/projects/objects/backgrounds/protos/TexturedBackgroundLight.proto"
EXTERNPROTO "https://raw.githubusercontent.com/cyberbotics/webots/R2023a/projects/objects/floors/protos/RectangleArena.proto"
EXTERNPROTO "https://raw.githubusercontent.com/cyberbotics/webots/R2023a/projects/devices/robotiq/protos/Robotiq3fGripper.proto"

WorldInfo {
}
Viewpoint {
  orientation -0.4877239246358079 -0.19457740677438426 0.8510376055796833 3.7962172549083446
  position 1.8679399952135674 1.1563953198258128 1.2120118877013628
}
TexturedBackground {
}
TexturedBackgroundLight {
}
RectangleArena {
  floorSize 7 7
}
Robot {
  children [
    Transform {
      translation -0.0602 0.0601 0.0252
      rotation 1 0 0 -3.1415923071795864
      children [
        DEF SCREW Group {
          children [
            Transform {
              scale 1.1 1.1 1.1
              children [
                Shape {
                  appearance PBRAppearance {
                    baseColorMap ImageTexture {
                      url [
                        "https://raw.githubusercontent.com/cyberbotics/webots/R2023a/projects/appearances/protos/textures/old_steel/old_steel_base_color.jpg"
                      ]
                    }
                    roughnessMap ImageTexture {
                      url [
                        "https://raw.githubusercontent.com/cyberbotics/webots/R2023a/projects/appearances/protos/textures/old_steel/old_steel_roughness.jpg"
                      ]
                    }
                    metalnessMap ImageTexture {
                      url [
                        "https://raw.githubusercontent.com/cyberbotics/webots/R2023a/projects/appearances/protos/textures/old_steel/old_steel_metalness.jpg"
                      ]
                    }
                    normalMap ImageTexture {
                      url [
                        "https://raw.githubusercontent.com/cyberbotics/webots/R2023a/projects/appearances/protos/textures/old_steel/old_steel_normal.jpg"
                      ]
                    }
                  }
                  geometry Mesh {
                    url [
                      "https://raw.githubusercontent.com/cyberbotics/webots/R2023a/projects/robots/universal_robots/protos/UR10e/meshes/screw.obj"
                    ]
                  }
                }
              ]
            }
            DEF CYLINDER Transform {
              translation 0 0 0.02
              rotation -0.7071067811865476 0.7071067811865476 0 -3.141593
              children [
                Shape {
                  appearance PBRAppearance {
                    baseColorMap ImageTexture {
                      url [
                        "https://raw.githubusercontent.com/cyberbotics/webots/R2023a/projects/appearances/protos/textures/screw_thread/screw_thread_base_color.jpg"
                      ]
                    }
                    roughnessMap ImageTexture {
                      url [
                        "https://raw.githubusercontent.com/cyberbotics/webots/R2023a/projects/appearances/protos/textures/screw_thread/screw_thread_roughness.jpg"
                      ]
                    }
                    normalMap ImageTexture {
                      url [
                        "https://raw.githubusercontent.com/cyberbotics/webots/R2023a/projects/appearances/protos/textures/screw_thread/screw_thread_normal.jpg"
                      ]
                    }
                    occlusionMap ImageTexture {
                      url [
                        "https://raw.githubusercontent.com/cyberbotics/webots/R2023a/projects/appearances/protos/textures/screw_thread/screw_thread_occlusion.jpg"
                      ]
                    }
                    textureTransform TextureTransform {
                      rotation 1.5708
                      scale 1.6 2
                    }
                  }
                  geometry Cylinder {
                    height 0.04
                    radius 0.0044
                  }
                }
              ]
            }
          ]
        }
      ]
    }
    Transform {
      translation -0.0602 -0.0602 0.0252
      rotation 1 0 0 -3.1415923071795864
      children [
        USE SCREW
      ]
    }
    Transform {
      translation 0.0602 -0.0602 0.0252
      rotation 1 0 0 -3.1415923071795864
      children [
        USE SCREW
      ]
    }
    Transform {
      translation 0.0602 0.0602 0.0252
      rotation 1 0 0 -3.1415923071795864
      children [
        USE SCREW
      ]
    }
    Shape {
      appearance DEF METAL_APPEARANCE PBRAppearance {
        baseColor 0.6 0.6 0.6
        roughness 0.7
      }
      geometry Mesh {
        url [
          "https://raw.githubusercontent.com/cyberbotics/webots/R2023a/projects/robots/universal_robots/protos/UR10e/meshes/base_link_0.obj"
        ]
      }
    }
    Shape {
      appearance DEF JOINT_APPEARANCE PBRAppearance {
        baseColor 0 0 0
        roughness 1
        metalness 0
      }
      geometry Mesh {
        url [
          "https://raw.githubusercontent.com/cyberbotics/webots/R2023a/projects/robots/universal_robots/protos/UR10e/meshes/base_link_1.obj"
        ]
      }
    }
    HingeJoint {
      jointParameters HingeJointParameters {
        position -0.00014753570655480478
        axis 0 0 1
        anchor 0 0 0.181
      }
      device [
        RotationalMotor {
          name "shoulder_pan_joint"
          maxVelocity 3.14
          minPosition -6.28318530718
          maxPosition 6.28318530718
          maxTorque 330
        }
        PositionSensor {
          name "shoulder_pan_joint_sensor"
        }
      ]
      endPoint Solid {
        translation 0 0 0.181
        rotation 0 0 -1 0.00014753570696239066
        children [
          Shape {
            appearance DEF SCREW_APPEARANCE PBRAppearance {
            }
            geometry Mesh {
              url [
                "https://raw.githubusercontent.com/cyberbotics/webots/R2023a/projects/robots/universal_robots/protos/UR10e/meshes/shoulder_link_0.obj"
              ]
            }
          }
          Shape {
            appearance USE METAL_APPEARANCE
            geometry Mesh {
              url [
                "https://raw.githubusercontent.com/cyberbotics/webots/R2023a/projects/robots/universal_robots/protos/UR10e/meshes/shoulder_link_1.obj"
              ]
            }
          }
          Shape {
            appearance USE JOINT_APPEARANCE
            geometry Mesh {
              url [
                "https://raw.githubusercontent.com/cyberbotics/webots/R2023a/projects/robots/universal_robots/protos/UR10e/meshes/shoulder_link_2.obj"
              ]
            }
          }
          Shape {
            appearance PBRAppearance {
              baseColor 0.490196 0.678431 0.8
              roughness 0.96875
              metalness 0
              normalMap ImageTexture {
                url [
                  "https://raw.githubusercontent.com/cyberbotics/webots/R2023a/projects/robots/universal_robots/protos/UR10e/textures/normal_0.jpg"
                ]
              }
              occlusionMap ImageTexture {
                url [
                  "https://raw.githubusercontent.com/cyberbotics/webots/R2023a/projects/robots/universal_robots/protos/UR10e/textures/occlusion_0.jpg"
                ]
              }
            }
            geometry Mesh {
              url [
                "https://raw.githubusercontent.com/cyberbotics/webots/R2023a/projects/robots/universal_robots/protos/UR10e/meshes/shoulder_link_3.obj"
              ]
            }
          }
          HingeJoint {
            jointParameters HingeJointParameters {
              position 0.00018248608573230056
              axis 0 1 0
              anchor 0 0.176 0
            }
            device [
              RotationalMotor {
                name "shoulder_lift_joint"
                maxVelocity 3.14
                minPosition -6.28318530718
                maxPosition 6.28318530718
                maxTorque 330
              }
              PositionSensor {
                name "shoulder_lift_joint_sensor"
              }
            ]
            endPoint Solid {
              translation 0 0.176 0
              rotation 0 1 0 1.570978486085732
              children [
                Shape {
                  appearance USE SCREW_APPEARANCE
                  geometry Mesh {
                    url [
                      "https://raw.githubusercontent.com/cyberbotics/webots/R2023a/projects/robots/universal_robots/protos/UR10e/meshes/upper_arm_link_0.obj"
                    ]
                  }
                }
                Shape {
                  appearance USE SCREW_APPEARANCE
                  geometry Mesh {
                    url [
                      "https://raw.githubusercontent.com/cyberbotics/webots/R2023a/projects/robots/universal_robots/protos/UR10e/meshes/upper_arm_link_1.obj"
                    ]
                  }
                }
                Shape {
                  appearance DEF METAL_APPEARANCE_LIGHT PBRAppearance {
                    roughness 0.7
                  }
                  geometry Mesh {
                    url [
                      "https://raw.githubusercontent.com/cyberbotics/webots/R2023a/projects/robots/universal_robots/protos/UR10e/meshes/upper_arm_link_2.obj"
                    ]
                  }
                }
                Shape {
                  appearance PBRAppearance {
                    baseColor 0.490196 0.678431 0.8
                    roughness 0.96875
                    metalness 0
                    normalMap ImageTexture {
                      url [
                        "https://raw.githubusercontent.com/cyberbotics/webots/R2023a/projects/robots/universal_robots/protos/UR10e/textures/normal_1.jpg"
                      ]
                    }
                    occlusionMap ImageTexture {
                      url [
                        "https://raw.githubusercontent.com/cyberbotics/webots/R2023a/projects/robots/universal_robots/protos/UR10e/textures/occlusion_1.jpg"
                      ]
                    }
                  }
                  geometry Mesh {
                    url [
                      "https://raw.githubusercontent.com/cyberbotics/webots/R2023a/projects/robots/universal_robots/protos/UR10e/meshes/upper_arm_link_3.obj"
                    ]
                  }
                }
                Shape {
                  appearance PBRAppearance {
                    baseColor 0.490196 0.678431 0.8
                    roughness 0.96875
                    metalness 0
                    normalMap ImageTexture {
                      url [
                        "https://raw.githubusercontent.com/cyberbotics/webots/R2023a/projects/robots/universal_robots/protos/UR10e/textures/normal_2.jpg"
                      ]
                    }
                    occlusionMap ImageTexture {
                      url [
                        "https://raw.githubusercontent.com/cyberbotics/webots/R2023a/projects/robots/universal_robots/protos/UR10e/textures/occlusion_2.jpg"
                      ]
                    }
                  }
                  geometry Mesh {
                    url [
                      "https://raw.githubusercontent.com/cyberbotics/webots/R2023a/projects/robots/universal_robots/protos/UR10e/meshes/upper_arm_link_4.obj"
                    ]
                  }
                }
                Shape {
                  appearance USE METAL_APPEARANCE
                  geometry Mesh {
                    url [
                      "https://raw.githubusercontent.com/cyberbotics/webots/R2023a/projects/robots/universal_robots/protos/UR10e/meshes/upper_arm_link_5.obj"
                    ]
                  }
                }
                Shape {
                  appearance USE JOINT_APPEARANCE
                  geometry Mesh {
                    url [
                      "https://raw.githubusercontent.com/cyberbotics/webots/R2023a/projects/robots/universal_robots/protos/UR10e/meshes/upper_arm_link_6.obj"
                    ]
                  }
                }
                Shape {
                  appearance USE METAL_APPEARANCE
                  geometry Mesh {
                    url [
                      "https://raw.githubusercontent.com/cyberbotics/webots/R2023a/projects/robots/universal_robots/protos/UR10e/meshes/upper_arm_link_7.obj"
                    ]
                  }
                }
                Shape {
                  appearance USE JOINT_APPEARANCE
                  geometry Mesh {
                    url [
                      "https://raw.githubusercontent.com/cyberbotics/webots/R2023a/projects/robots/universal_robots/protos/UR10e/meshes/upper_arm_link_8.obj"
                    ]
                  }
                }
                Shape {
                  appearance USE JOINT_APPEARANCE
                  geometry Mesh {
                    url [
                      "https://raw.githubusercontent.com/cyberbotics/webots/R2023a/projects/robots/universal_robots/protos/UR10e/meshes/upper_arm_link_9.obj"
                    ]
                  }
                }
                HingeJoint {
                  jointParameters HingeJointParameters {
                    position 2.3187963343211293e-05
                    axis 0 1 0
                    anchor 0 -0.137 0.613
                  }
                  device [
                    RotationalMotor {
                      name "elbow_joint"
                      maxVelocity 3.14
                      minPosition -3.14159265359
                      maxPosition 3.14159265359
                      maxTorque 150
                    }
                    PositionSensor {
                      name "elbow_joint_sensor"
                    }
                  ]
                  endPoint Solid {
                    translation 0 -0.137 0.613
                    rotation 0 1 0 2.3187968841845678e-05
                    children [
                      Shape {
                        appearance USE SCREW_APPEARANCE
                        geometry Mesh {
                          url [
                            "https://raw.githubusercontent.com/cyberbotics/webots/R2023a/projects/robots/universal_robots/protos/UR10e/meshes/forearm_link_0.obj"
                          ]
                        }
                      }
                      Shape {
                        appearance USE METAL_APPEARANCE_LIGHT
                        geometry Mesh {
                          url [
                            "https://raw.githubusercontent.com/cyberbotics/webots/R2023a/projects/robots/universal_robots/protos/UR10e/meshes/forearm_link_1.obj"
                          ]
                        }
                      }
                      Shape {
                        appearance USE METAL_APPEARANCE
                        geometry Mesh {
                          url [
                            "https://raw.githubusercontent.com/cyberbotics/webots/R2023a/projects/robots/universal_robots/protos/UR10e/meshes/forearm_link_2.obj"
                          ]
                        }
                      }
                      Shape {
                        appearance USE JOINT_APPEARANCE
                        geometry Mesh {
                          url [
                            "https://raw.githubusercontent.com/cyberbotics/webots/R2023a/projects/robots/universal_robots/protos/UR10e/meshes/forearm_link_3.obj"
                          ]
                        }
                      }
                      Shape {
                        appearance PBRAppearance {
                          baseColor 0.490196 0.678431 0.8
                          roughness 0.96875
                          metalness 0
                          normalMap ImageTexture {
                            url [
                              "https://raw.githubusercontent.com/cyberbotics/webots/R2023a/projects/robots/universal_robots/protos/UR10e/textures/normal_3.jpg"
                            ]
                          }
                          occlusionMap ImageTexture {
                            url [
                              "https://raw.githubusercontent.com/cyberbotics/webots/R2023a/projects/robots/universal_robots/protos/UR10e/textures/occlusion_3.jpg"
                            ]
                          }
                        }
                        geometry Mesh {
                          url [
                            "https://raw.githubusercontent.com/cyberbotics/webots/R2023a/projects/robots/universal_robots/protos/UR10e/meshes/forearm_link_4.obj"
                          ]
                        }
                      }
                      Shape {
                        appearance USE METAL_APPEARANCE
                        geometry Mesh {
                          url [
                            "https://raw.githubusercontent.com/cyberbotics/webots/R2023a/projects/robots/universal_robots/protos/UR10e/meshes/forearm_link_5.obj"
                          ]
                        }
                      }
                      Shape {
                        appearance USE JOINT_APPEARANCE
                        geometry Mesh {
                          url [
                            "https://raw.githubusercontent.com/cyberbotics/webots/R2023a/projects/robots/universal_robots/protos/UR10e/meshes/forearm_link_6.obj"
                          ]
                        }
                      }
                      Shape {
                        appearance USE JOINT_APPEARANCE
                        geometry Mesh {
                          url [
                            "https://raw.githubusercontent.com/cyberbotics/webots/R2023a/projects/robots/universal_robots/protos/UR10e/meshes/forearm_link_7.obj"
                          ]
                        }
                      }
                      HingeJoint {
                        jointParameters HingeJointParameters {
                          position -7.248870102025466e-05
                          axis 0 1 0
                          anchor 0 0 0.571
                        }
                        device [
                          RotationalMotor {
                            name "wrist_1_joint"
                            maxVelocity 6.28
                            minPosition -6.28318530718
                            maxPosition 6.28318530718
                            maxTorque 54
                          }
                          PositionSensor {
                            name "wrist_1_joint_sensor"
                          }
                        ]
                        endPoint Solid {
                          translation 0 0 0.571
                          rotation 0 0.9999999999999999 0 1.5707235112989788
                          children [
                            Shape {
                              appearance USE SCREW_APPEARANCE
                              geometry Mesh {
                                url [
                                  "https://raw.githubusercontent.com/cyberbotics/webots/R2023a/projects/robots/universal_robots/protos/UR10e/meshes/wrist_1_link_0.obj"
                                ]
                              }
                            }
                            Shape {
                              appearance USE METAL_APPEARANCE
                              geometry Mesh {
                                url [
                                  "https://raw.githubusercontent.com/cyberbotics/webots/R2023a/projects/robots/universal_robots/protos/UR10e/meshes/wrist_1_link_1.obj"
                                ]
                              }
                            }
                            Shape {
                              appearance PBRAppearance {
                                baseColor 0.490196 0.678431 0.8
                                roughness 0.96875
                                metalness 0
                                normalMap ImageTexture {
                                  url [
                                    "https://raw.githubusercontent.com/cyberbotics/webots/R2023a/projects/robots/universal_robots/protos/UR10e/textures/normal_4.jpg"
                                  ]
                                }
                                occlusionMap ImageTexture {
                                  url [
                                    "https://raw.githubusercontent.com/cyberbotics/webots/R2023a/projects/robots/universal_robots/protos/UR10e/textures/occlusion_4.jpg"
                                  ]
                                }
                              }
                              geometry Mesh {
                                url [
                                  "https://raw.githubusercontent.com/cyberbotics/webots/R2023a/projects/robots/universal_robots/protos/UR10e/meshes/wrist_1_link_2.obj"
                                ]
                              }
                            }
                            Shape {
                              appearance USE JOINT_APPEARANCE
                              geometry Mesh {
                                url [
                                  "https://raw.githubusercontent.com/cyberbotics/webots/R2023a/projects/robots/universal_robots/protos/UR10e/meshes/wrist_1_link_3.obj"
                                ]
                              }
                            }
                            HingeJoint {
                              jointParameters HingeJointParameters {
                                position -4.489639638507744e-05
                                axis 0 0 1
                                anchor 0 0.135 0
                              }
                              device [
                                RotationalMotor {
                                  name "wrist_2_joint"
                                  maxVelocity 6.28
                                  minPosition -6.28318530718
                                  maxPosition 6.28318530718
                                  maxTorque 54
                                }
                                PositionSensor {
                                  name "wrist_2_joint_sensor"
                                }
                              ]
                              endPoint Solid {
                                translation 0 0.135 0
                                rotation 0 0 -1 4.489639500712403e-05
                                children [
                                  Shape {
                                    appearance USE SCREW_APPEARANCE
                                    geometry Mesh {
                                      url [
                                        "https://raw.githubusercontent.com/cyberbotics/webots/R2023a/projects/robots/universal_robots/protos/UR10e/meshes/wrist_2_link_0.obj"
                                      ]
                                    }
                                  }
                                  Shape {
                                    appearance USE METAL_APPEARANCE
                                    geometry Mesh {
                                      url [
                                        "https://raw.githubusercontent.com/cyberbotics/webots/R2023a/projects/robots/universal_robots/protos/UR10e/meshes/wrist_2_link_1.obj"
                                      ]
                                    }
                                  }
                                  Shape {
                                    appearance PBRAppearance {
                                      baseColor 0.490196 0.678431 0.8
                                      roughness 0.96875
                                      metalness 0
                                      normalMap ImageTexture {
                                        url [
                                          "https://raw.githubusercontent.com/cyberbotics/webots/R2023a/projects/robots/universal_robots/protos/UR10e/textures/normal_5.jpg"
                                        ]
                                      }
                                      occlusionMap ImageTexture {
                                        url [
                                          "https://raw.githubusercontent.com/cyberbotics/webots/R2023a/projects/robots/universal_robots/protos/UR10e/textures/occlusion_5.jpg"
                                        ]
                                      }
                                    }
                                    geometry Mesh {
                                      url [
                                        "https://raw.githubusercontent.com/cyberbotics/webots/R2023a/projects/robots/universal_robots/protos/UR10e/meshes/wrist_2_link_2.obj"
                                      ]
                                    }
                                  }
                                  Shape {
                                    appearance USE JOINT_APPEARANCE
                                    geometry Mesh {
                                      url [
                                        "https://raw.githubusercontent.com/cyberbotics/webots/R2023a/projects/robots/universal_robots/protos/UR10e/meshes/wrist_2_link_3.obj"
                                      ]
                                    }
                                  }
                                  HingeJoint {
                                    jointParameters HingeJointParameters {
                                      position -4.408880835323917e-05
                                      axis 0 1 0
                                      anchor 0 0 0.12
                                    }
                                    device [
                                      RotationalMotor {
                                        name "wrist_3_joint"
                                        maxVelocity 6.28
                                        minPosition -6.28318530718
                                        maxPosition 6.28318530718
                                        maxTorque 54
                                      }
                                      PositionSensor {
                                        name "wrist_3_joint_sensor"
                                      }
                                    ]
                                    endPoint Solid {
                                      translation 8.129723679886132e-06 -5.420437992897931e-07 0.11988737640802269
                                      rotation -0.7042268313528427 -0.7089756925375897 -0.03765683727531849 3.1540601897811987e-05
                                      children [
                                        Shape {
                                          appearance USE METAL_APPEARANCE
                                          geometry Mesh {
                                            url [
                                              "https://raw.githubusercontent.com/cyberbotics/webots/R2023a/projects/robots/universal_robots/protos/UR10e/meshes/wrist_3_link_0.obj"
                                            ]
                                          }
                                        }
                                        Transform {
                                          translation 0 0.12 0
                                          children [
                                            Robotiq3fGripper {
                                              hidden position_0_0 -1.0737926222859073e-05
                                              hidden position_0_1 -1.073717961652676e-05
                                              hidden position_0_2 0.04949978694843783
                                              hidden rotation_1 0.7068252250896219 0.7073882252175062 -7.949183739361257e-07 3.141590404118965
                                              hidden position_1_0 0.04950582528602857
                                              hidden rotation_2 0 0 1 5.825267779517691e-06
                                              hidden position_2_0 -3.099354269833593e-08
                                              hidden rotation_3 0 0 -1 0.5200000309935428
                                              hidden position_3_0 -0.05230000000008768
                                              hidden rotation_5 0.7068252250896203 0.7073882252175083 -7.94654513788181e-07 3.141590404647105
                                              hidden position_5_0 0.04950582565358636
                                              hidden rotation_6 0 0 1 5.825648941979381e-06
                                              hidden position_6_0 -3.099383683036194e-08
                                              hidden rotation_7 0 0 -1 0.5200000309938372
                                              hidden position_7_0 -0.05230000000009059
                                              hidden rotation_9 0 0 -1 2.1283115233608642e-07
                                              hidden position_9_0 3.098295758052744e-08
                                              hidden rotation_10 0 0 -1 0.5199999690170422
                                              hidden position_10_0 -0.05229999999995737
                                            }
                                          ]
                                        }
                                      ]
                                      name "wrist_3_link"
                                      boundingObject Group {
                                        children [
                                          Transform {
                                            translation 0 0.086 0
                                            rotation 1 0 0 -1.570796
                                            children [
                                              Cylinder {
                                                height 0.048
                                                radius 0.045
                                              }
                                            ]
                                          }
                                          Transform {
                                            translation 0 0.109 0
                                            rotation 1 0 0 -1.570796
                                            children [
                                              Cylinder {
                                                height 0.018
                                                radius 0.032
                                              }
                                            ]
                                          }
                                        ]
                                      }
                                      physics Physics {
                                        density -1
                                        mass 0.615
                                        centerOfMass [
                                          0 0 0
                                        ]
                                      }
                                      linearVelocity -3.6466835170206484e-05 1.0696278282196043e-05 0.0003619766986257209
                                      angularVelocity -5.305385514057865e-05 -0.0011906261690863018 0.00037407332133778336
                                    }
                                  }
                                ]
                                name "wrist_2_link"
                                boundingObject Group {
                                  children [
                                    Transform {
                                      translation 0 0.007 0.1195
                                      rotation 1 0 0 -1.570796
                                      children [
                                        Cylinder {
                                          height 0.12
                                          radius 0.047
                                        }
                                      ]
                                    }
                                    Transform {
                                      translation 0 0 0.0805
                                      rotation 1 0 0 3.141593
                                      children [
                                        Cylinder {
                                          height 0.043
                                          radius 0.046
                                        }
                                      ]
                                    }
                                  ]
                                }
                                physics Physics {
                                  density -1
                                  mass 1.98
                                  centerOfMass [
                                    0 0.007 0.119
                                  ]
                                }
                                linearVelocity 1.0291895040798137e-05 4.3595922427433514e-05 0.00038096636214350664
                                angularVelocity -4.8568161362827736e-05 -0.000967907525867088 0.0003821967792341928
                              }
                            }
                          ]
                          name "wrist_1_link"
                          boundingObject Group {
                            children [
                              Transform {
                                translation 0 0.095 0
                                rotation 1 0 0 -1.570796
                                children [
                                  Cylinder {
                                    height 0.075
                                    radius 0.045
                                  }
                                ]
                              }
                              Transform {
                                translation 0 0.134 0.007
                                rotation 1 0 0 3.141593
                                children [
                                  Cylinder {
                                    height 0.126
                                    radius 0.048
                                  }
                                ]
                              }
                            ]
                          }
                          physics Physics {
                            density -1
                            mass 2.1
                            centerOfMass [
                              0 0.118 0.007
                            ]
                          }
                          linearVelocity -7.947929357079547e-05 8.19935848487657e-05 0.00039631462196498867
                          angularVelocity -4.0213832485475035e-05 -0.0009705438757599593 0.0001613910657738764
                        }
                      }
                    ]
                    name "forearm_link"
                    boundingObject Group {
                      children [
                        Transform {
                          translation 0 0 0.307
                          rotation 1 0 0 3.141593
                          children [
                            Cylinder {
                              height 0.49
                              radius 0.047
                            }
                          ]
                        }
                        Transform {
                          translation 0 0.009 0.57
                          rotation 1 0 0 -1.570796
                          children [
                            Cylinder {
                              height 0.129
                              radius 0.046
                            }
                          ]
                        }
                        Transform {
                          translation 0 0.06 0
                          rotation 1 0 0 -1.570796
                          children [
                            Capsule {
                              height 0.05
                              radius 0.058
                              subdivision 16
                            }
                          ]
                        }
                        Transform {
                          translation 0 0 0.05
                          children [
                            Capsule {
                              height 0.03
                              radius 0.057
                              subdivision 16
                            }
                          ]
                        }
                      ]
                    }
                    physics Physics {
                      density -1
                      mass 3.989
                      centerOfMass [
                        0 0 0
                      ]
                    }
                    linearVelocity -5.4202978731261754e-05 1.9453512812771365e-05 3.903952223505323e-05
                    angularVelocity -2.979265134541987e-05 -0.0006595284958683071 0.00016773455770709874
                  }
                }
              ]
              name "upper_arm_link"
              boundingObject Group {
                children [
                  Transform {
                    translation 0 0 0.33
                    rotation 1 0 0 3.141593
                    children [
                      Cylinder {
                        height 0.463
                        radius 0.058
                      }
                    ]
                  }
                  Transform {
                    translation 0 0 0.06
                    rotation 1 0 0 3.141593
                    children [
                      Cylinder {
                        height 0.1
                        radius 0.076
                      }
                    ]
                  }
                  Transform {
                    rotation 1 0 0 -1.570796
                    children [
                      Cylinder {
                        height 0.183
                        radius 0.077
                      }
                    ]
                  }
                  Transform {
                    translation 0 -0.005 0.612
                    rotation 1 0 0 -1.570796
                    children [
                      Cylinder {
                        height 0.149
                        radius 0.061
                      }
                    ]
                  }
                ]
              }
              physics Physics {
                density -1
                mass 13.051
                centerOfMass [
                  0 0 0.3065
                ]
              }
              linearVelocity -6.761037722553813e-05 -6.683565102261396e-06 9.913503869267837e-06
              angularVelocity -1.9330498897933812e-05 -0.00013416840395373146 0.00019290456877543927
            }
          }
        ]
        name "shoulder_link"
        boundingObject Group {
          children [
            Transform {
              rotation 1 0 0 3.141593
              children [
                Cylinder {
                  height 0.183
                  radius 0.077
                }
              ]
            }
            Transform {
              translation 0 0.05 0
              rotation 1 0 0 1.570797
              children [
                Cylinder {
                  height 0.093
                  radius 0.076
                }
              ]
            }
          ]
        }
        physics Physics {
          density -1
          mass 7.369
          centerOfMass [
            0 0 0
          ]
        }
        linearVelocity -1.2665413747113252e-05 -3.2863760968581605e-05 -1.4616617156069227e-05
        angularVelocity -1.0936270441228378e-05 2.0058654182558483e-05 0.00024010719412753085
      }
    }
  ]
  name "UR10e"
  model "UR10e"
  boundingObject Transform {
    translation 0 0 0.05
    rotation 1 0 0 3.141593
    children [
      Cylinder {
        height 0.1
        radius 0.095
      }
    ]
  }
  selfCollision TRUE
}
